Workbook

Sheet Données brutes
A1: TABLEAU DE BORD KPI LOGISTIQUE — DONNÉES BRUTES
A2: Saisie continue — une ligne par mouvement (livraison, rupture, retard). Ne jamais remplir en une seule fois en fin de mois.
A3: Date de commande | B3: Date de livraison réelle | C3: Site | D3: Article | E3: Qté commandée | F3: Qté livrée | G3: Statut | H3: Coût total (USD) | I3: Bénéficiaires couverts | J3: Incident (texte libre) | K3: Délai (jours)
A4: 46205 | B4: 46212 | C4: Goma | D4: Kits médicaux | E4: 200 | F4: 200 | G4: Livré | H4: 4200 | I4: 1800 | K4: =IF(AND(A4<>"",B4<>""),B4-A4,"") -> 7
A5: 46206 | B5: 46218 | C5: Goma | D5: Bâches plastiques | E5: 500 | F5: 500 | G5: Livré | H5: 3100 | I5: 2200 | K5: =IF(AND(A5<>"",B5<>""),B5-A5,"") -> 12
A6: 46208 | C6: Goma | D6: Intrants nutritionnels | E6: 300 | F6: 0 | G6: Rupture | H6: 0 | I6: 0 | J6: Fournisseur en rupture, relance en cours | K6: =IF(AND(A6<>"",B6<>""),B6-A6,"")
A7: 46211 | B7: 46223 | C7: Goma | D7: Kits WASH | E7: 150 | F7: 150 | G7: Livré | H7: 2600 | I7: 1500 | K7: =IF(AND(A7<>"",B7<>""),B7-A7,"") -> 12
A8: 46213 | B8: 46233 | C8: Goma | D8: Pièces détachées véhicule | E8: 10 | F8: 10 | G8: Retard | H8: 900 | I8: 0 | J8: Retard dédouanement 8 jours | K8: =IF(AND(A8<>"",B8<>""),B8-A8,"") -> 20
A9: 46204 | B9: 46209 | C9: Abéché | D9: Carburant (fûts) | E9: 40 | F9: 40 | G9: Livré | H9: 5200 | I9: 3000 | K9: =IF(AND(A9<>"",B9<>""),B9-A9,"") -> 5
A10: 46207 | B10: 46214 | C10: Abéché | D10: Kits médicaux | E10: 120 | F10: 120 | G10: Livré | H10: 2500 | I10: 1100 | K10: =IF(AND(A10<>"",B10<>""),B10-A10,"") -> 7
A11: 46209 | B11: 46217 | C11: Abéché | D11: Bâches plastiques | E11: 300 | F11: 280 | G11: Livré | H11: 1800 | I11: 1300 | J11: 20 unités endommagées au transport | K11: =IF(AND(A11<>"",B11<>""),B11-A11,"") -> 8
A12: 46215 | C12: Abéché | D12: Intrants nutritionnels | E12: 200 | F12: 0 | G12: Rupture | H12: 0 | I12: 0 | J12: Stock épuisé, seuil de commande dépassé | K12: =IF(AND(A12<>"",B12<>""),B12-A12,"")
A13: 46218 | B13: 46226 | C13: Abéché | D13: Kits WASH | E13: 100 | F13: 100 | G13: Livré | H13: 1700 | I13: 900 | K13: =IF(AND(A13<>"",B13<>""),B13-A13,"") -> 8
A14: 46205 | B14: 46211 | C14: Juba | D14: Kits médicaux | E14: 180 | F14: 180 | G14: Livré | H14: 3800 | I14: 1600 | K14: =IF(AND(A14<>"",B14<>""),B14-A14,"") -> 6
A15: 46208 | B15: 46222 | C15: Juba | D15: Pièces détachées véhicule | E15: 8 | F15: 8 | G15: Retard | H15: 1100 | I15: 0 | J15: Camion immobilisé 9 jours pour panne | K15: =IF(AND(A15<>"",B15<>""),B15-A15,"") -> 14
A16: 46212 | B16: 46219 | C16: Juba | D16: Carburant (fûts) | E16: 35 | F16: 35 | G16: Livré | H16: 4600 | I16: 2500 | K16: =IF(AND(A16<>"",B16<>""),B16-A16,"") -> 7
A17: 46214 | B17: 46228 | C17: Juba | D17: Bâches plastiques | E17: 260 | F17: 260 | G17: Livré | H17: 2100 | I17: 1400 | K17: =IF(AND(A17<>"",B17<>""),B17-A17,"") -> 14
A18: 46217 | B18: 46224 | C18: Juba | D18: Kits WASH | E18: 90 | F18: 90 | G18: Livré | H18: 1500 | I18: 700 | K18: =IF(AND(A18<>"",B18<>""),B18-A18,"") -> 7
A19: 46204 | B19: 46210 | C19: Maiduguri | D19: Kits médicaux | E19: 220 | F19: 220 | G19: Livré | H19: 4700 | I19: 2100 | K19: =IF(AND(A19<>"",B19<>""),B19-A19,"") -> 6
A20: 46206 | B20: 46212 | C20: Maiduguri | D20: Intrants nutritionnels | E20: 300 | F20: 300 | G20: Livré | H20: 3300 | I20: 2400 | K20: =IF(AND(A20<>"",B20<>""),B20-A20,"") -> 6
A21: 46209 | C21: Maiduguri Nord | D21: Intrants nutritionnels | E21: 150 | F21: 0 | G21: Rupture | H21: 0 | I21: 0 | J21: Carnet papier site secondaire, saisi a posteriori | K21: =IF(AND(A21<>"",B21<>""),B21-A21,"")
A22: 46213 | B22: 46219 | C22: Maiduguri | D22: Bâches plastiques | E22: 400 | F22: 400 | G22: Livré | H22: 2900 | I22: 2000 | K22: =IF(AND(A22<>"",B22<>""),B22-A22,"") -> 6
A23: 46216 | B23: 46225 | C23: Maiduguri | D23: Kits WASH | E23: 130 | F23: 130 | G23: Livré | H23: 2000 | I23: 1000 | K23: =IF(AND(A23<>"",B23<>""),B23-A23,"") -> 9
A24: 46219 | B24: 46227 | C24: Maiduguri | D24: Carburant (fûts) | E24: 30 | F24: 30 | G24: Livré | H24: 3900 | I24: 1800 | K24: =IF(AND(A24<>"",B24<>""),B24-A24,"") -> 8
A25: 46221 | B25: 46229 | C25: Goma | D25: Carburant (fûts) | E25: 25 | F25: 25 | G25: Livré | H25: 3400 | I25: 1600 | K25: =IF(AND(A25<>"",B25<>""),B25-A25,"") -> 8
A26: 46223 | B26: 46231 | C26: Abéché | D26: Pièces détachées véhicule | E26: 6 | F26: 6 | G26: Livré | H26: 800 | I26: 0 | K26: =IF(AND(A26<>"",B26<>""),B26-A26,"") -> 8
A27: 46224 | B27: 46230 | C27: Juba | D27: Intrants nutritionnels | E27: 210 | F27: 210 | G27: Livré | H27: 2700 | I27: 1900 | K27: =IF(AND(A27<>"",B27<>""),B27-A27,"") -> 6
A28: 46225 | B28: 46236 | C28: Maiduguri | D28: Kits médicaux | E28: 160 | F28: 160 | G28: Retard | H28: 3100 | I28: 1400 | J28: Retard contrôle qualité | K28: =IF(AND(A28<>"",B28<>""),B28-A28,"") -> 11
K29: =IF(AND(A29<>"",B29<>""),B29-A29,"")
K30: =IF(AND(A30<>"",B30<>""),B30-A30,"")
K31: =IF(AND(A31<>"",B31<>""),B31-A31,"")
K32: =IF(AND(A32<>"",B32<>""),B32-A32,"")
K33: =IF(AND(A33<>"",B33<>""),B33-A33,"")
K34: =IF(AND(A34<>"",B34<>""),B34-A34,"")
K35: =IF(AND(A35<>"",B35<>""),B35-A35,"")
K36: =IF(AND(A36<>"",B36<>""),B36-A36,"")
K37: =IF(AND(A37<>"",B37<>""),B37-A37,"")
K38: =IF(AND(A38<>"",B38<>""),B38-A38,"")
K39: =IF(AND(A39<>"",B39<>""),B39-A39,"")
K40: =IF(AND(A40<>"",B40<>""),B40-A40,"")
...

Sheet Tableau de bord KPI
A1: TABLEAU DE BORD KPI LOGISTIQUE — JUILLET 2026
A2: Les cellules ci-dessous sont calculées automatiquement à partir de l'onglet "Données brutes". Ne pas saisir de valeur en dur.
A4: Taux de rupture de stock global | C4: Lead time moyen (jours, commandes livrées) | E4: Coût par bénéficiaire (USD)
A5: =IFERROR(COUNTIFS('Données brutes'!$G$4:$G$200,"Rupture")/COUNTA('Données brutes'!$G$4:$G$200),"N/A") -> 0.12 | C5: =IFERROR(AVERAGEIFS('Données brutes'!$K$4:$K$200,'Données brutes'!$G$4:$G$200,"Livré"),"N/A") -> 7.8947368 | E5: =IFERROR(SUM('Données brutes'!$H$4:$H$200)/SUM('Données brutes'!$I$4:$I$200),"N/A") -> 1.9223602
A7: Récapitulatif par site
A8: Site | B8: Taux de rupture | C8: Lead time moyen (j) | D8: Coût / bénéficiaire (USD) | E8: Nb lignes
A9: Goma | B9: =IFERROR(COUNTIFS('Données brutes'!$C$4:$C$200,$A9,'Données brutes'!$G$4:$G$200,"Rupture")/COUNTIFS('Données brutes'!$C$4:$C$200,$A9),"N/A") -> 0.16666667 | C9: =IFERROR(AVERAGEIFS('Données brutes'!$K$4:$K$200,'Données brutes'!$C$4:$C$200,$A9,'Données brutes'!$G$4:$G$200,"Livré"),"N/A") -> 9.75 | D9: =IFERROR(SUMIFS('Données brutes'!$H$4:$H$200,'Données brutes'!$C$4:$C$200,$A9)/SUMIFS('Données brutes'!$I$4:$I$200,'Données brutes'!$C$4:$C$200,$A9),"N/A") -> 2 | E9: =COUNTIFS('Données brutes'!$C$4:$C$200,$A9) -> 6
A10: Abéché | B10: =IFERROR(COUNTIFS('Données brutes'!$C$4:$C$200,$A10,'Données brutes'!$G$4:$G$200,"Rupture")/COUNTIFS('Données brutes'!$C$4:$C$200,$A10),"N/A") -> 0.16666667 | C10: =IFERROR(AVERAGEIFS('Données brutes'!$K$4:$K$200,'Données brutes'!$C$4:$C$200,$A10,'Données brutes'!$G$4:$G$200,"Livré"),"N/A") -> 7.2 | D10: =IFERROR(SUMIFS('Données brutes'!$H$4:$H$200,'Données brutes'!$C$4:$C$200,$A10)/SUMIFS('Données brutes'!$I$4:$I$200,'Données brutes'!$C$4:$C$200,$A10),"N/A") -> 1.9047619 | E10: =COUNTIFS('Données brutes'!$C$4:$C$200,$A10) -> 6
A11: Juba | B11: =IFERROR(COUNTIFS('Données brutes'!$C$4:$C$200,$A11,'Données brutes'!$G$4:$G$200,"Rupture")/COUNTIFS('Données brutes'!$C$4:$C$200,$A11),"N/A") -> 0 | C11: =IFERROR(AVERAGEIFS('Données brutes'!$K$4:$K$200,'Données brutes'!$C$4:$C$200,$A11,'Données brutes'!$G$4:$G$200,"Livré"),"N/A") -> 8 | D11: =IFERROR(SUMIFS('Données brutes'!$H$4:$H$200,'Données brutes'!$C$4:$C$200,$A11)/SUMIFS('Données brutes'!$I$4:$I$200,'Données brutes'!$C$4:$C$200,$A11),"N/A") -> 1.9506173 | E11: =COUNTIFS('Données brutes'!$C$4:$C$200,$A11) -> 6
A12: Maiduguri | B12: =IFERROR(COUNTIFS('Données brutes'!$C$4:$C$200,$A12,'Données brutes'!$G$4:$G$200,"Rupture")/COUNTIFS('Données brutes'!$C$4:$C$200,$A12),"N/A") -> 0 | C12: =IFERROR(AVERAGEIFS('Données brutes'!$K$4:$K$200,'Données brutes'!$C$4:$C$200,$A12,'Données brutes'!$G$4:$G$200,"Livré"),"N/A") -> 7 | D12: =IFERROR(SUMIFS('Données brutes'!$H$4:$H$200,'Données brutes'!$C$4:$C$200,$A12)/SUMIFS('Données brutes'!$I$4:$I$200,'Données brutes'!$C$4:$C$200,$A12),"N/A") -> 1.8598131 | E12: =COUNTIFS('Données brutes'!$C$4:$C$200,$A12) -> 6
A14: Note : "Maiduguri Nord" (orthographe non standardisée dans les données brutes) n'est volontairement pas listé ici — voir Module 03-Exercices sur les pièges de saisie incohérente.
