Workbook

Sheet Suivi dossiers
A1: CHECKLIST DE DEDOUANEMENT HUMANITAIRE
A2: Formation en Logistique Humanitaire · Module 06 · BK-BOOST Ltd.
A4: Shipment ID | B4: Origine | C4: Description marchandise | D4: Date ouverture dossier | E4: Document requis | F4: Statut | G4: Date obtenue | H4: Responsable | I4: Jours ecoules | J4: Alerte
A5: TCD-2026-011 | B5: Douala, Cameroun | C5: Kits sanitaires + moustiquaires | D5: 46240 | E5: Facture commerciale | F5: Obtenu | G5: 46245 | H5: A. Mbeki (transitaire) | I5: =IF(OR(F5="Obtenu",F5="Non applicable",D5=""),"",TODAY()-D5) | J5: =IF(AND(F5<>"Obtenu",F5<>"Non applicable",D5<>"",(TODAY()-D5)>5),"RETARD","")
A6: TCD-2026-011 | B6: Douala, Cameroun | C6: Kits sanitaires + moustiquaires | D6: 46240 | E6: Liste de colisage (packing list) | F6: Obtenu | G6: 46245 | H6: A. Mbeki (transitaire) | I6: =IF(OR(F6="Obtenu",F6="Non applicable",D6=""),"",TODAY()-D6) | J6: =IF(AND(F6<>"Obtenu",F6<>"Non applicable",D6<>"",(TODAY()-D6)>5),"RETARD","")
A7: TCD-2026-011 | B7: Douala, Cameroun | C7: Kits sanitaires + moustiquaires | D7: 46240 | E7: Certificat d'origine | F7: Obtenu | G7: 46245 | H7: A. Mbeki (transitaire) | I7: =IF(OR(F7="Obtenu",F7="Non applicable",D7=""),"",TODAY()-D7) | J7: =IF(AND(F7<>"Obtenu",F7<>"Non applicable",D7<>"",(TODAY()-D7)>5),"RETARD","")
A8: TCD-2026-011 | B8: Douala, Cameroun | C8: Kits sanitaires + moustiquaires | D8: 46240 | E8: Demande d'exoneration douaniere | F8: Obtenu | G8: 46245 | H8: A. Mbeki (transitaire) | I8: =IF(OR(F8="Obtenu",F8="Non applicable",D8=""),"",TODAY()-D8) | J8: =IF(AND(F8<>"Obtenu",F8<>"Non applicable",D8<>"",(TODAY()-D8)>5),"RETARD","")
A9: TCD-2026-011 | B9: Douala, Cameroun | C9: Kits sanitaires + moustiquaires | D9: 46240 | E9: Autorisation d'importation | F9: Obtenu | G9: 46245 | H9: A. Mbeki (transitaire) | I9: =IF(OR(F9="Obtenu",F9="Non applicable",D9=""),"",TODAY()-D9) | J9: =IF(AND(F9<>"Obtenu",F9<>"Non applicable",D9<>"",(TODAY()-D9)>5),"RETARD","")
A10: TCD-2026-011 | B10: Douala, Cameroun | C10: Kits sanitaires + moustiquaires | D10: 46240 | E10: Manifeste de cargaison | F10: Obtenu | G10: 46245 | H10: A. Mbeki (transitaire) | I10: =IF(OR(F10="Obtenu",F10="Non applicable",D10=""),"",TODAY()-D10) | J10: =IF(AND(F10<>"Obtenu",F10<>"Non applicable",D10<>"",(TODAY()-D10)>5),"RETARD","")
A11: TCD-2026-011 | B11: Douala, Cameroun | C11: Kits sanitaires + moustiquaires | D11: 46240 | E11: Autorisation ministerielle complementaire (si applicable) | F11: Obtenu | G11: 46245 | H11: A. Mbeki (transitaire) | I11: =IF(OR(F11="Obtenu",F11="Non applicable",D11=""),"",TODAY()-D11) | J11: =IF(AND(F11<>"Obtenu",F11<>"Non applicable",D11<>"",(TODAY()-D11)>5),"RETARD","")
A12: TCD-2026-012 | B12: Douala, Cameroun | C12: Vehicule de secours 4x4 | D12: 46253 | E12: Facture commerciale | F12: Obtenu | G12: 46254 | H12: A. Mbeki (transitaire) | I12: =IF(OR(F12="Obtenu",F12="Non applicable",D12=""),"",TODAY()-D12) | J12: =IF(AND(F12<>"Obtenu",F12<>"Non applicable",D12<>"",(TODAY()-D12)>5),"RETARD","")
A13: TCD-2026-012 | B13: Douala, Cameroun | C13: Vehicule de secours 4x4 | D13: 46253 | E13: Liste de colisage (packing list) | F13: Obtenu | G13: 46254 | H13: A. Mbeki (transitaire) | I13: =IF(OR(F13="Obtenu",F13="Non applicable",D13=""),"",TODAY()-D13) | J13: =IF(AND(F13<>"Obtenu",F13<>"Non applicable",D13<>"",(TODAY()-D13)>5),"RETARD","")
A14: TCD-2026-012 | B14: Douala, Cameroun | C14: Vehicule de secours 4x4 | D14: 46253 | E14: Certificat d'origine | F14: Obtenu | G14: 46255 | H14: A. Mbeki (transitaire) | I14: =IF(OR(F14="Obtenu",F14="Non applicable",D14=""),"",TODAY()-D14) | J14: =IF(AND(F14<>"Obtenu",F14<>"Non applicable",D14<>"",(TODAY()-D14)>5),"RETARD","")
A15: TCD-2026-012 | B15: Douala, Cameroun | C15: Vehicule de secours 4x4 | D15: 46253 | E15: Demande d'exoneration douaniere | F15: Bloque | H15: Point focal ONG | I15: =IF(OR(F15="Obtenu",F15="Non applicable",D15=""),"",TODAY()-D15) | J15: =IF(AND(F15<>"Obtenu",F15<>"Non applicable",D15<>"",(TODAY()-D15)>5),"RETARD","")
A16: TCD-2026-012 | B16: Douala, Cameroun | C16: Vehicule de secours 4x4 | D16: 46253 | E16: Autorisation d'importation | F16: En attente | H16: Ministere des Transports | I16: =IF(OR(F16="Obtenu",F16="Non applicable",D16=""),"",TODAY()-D16) | J16: =IF(AND(F16<>"Obtenu",F16<>"Non applicable",D16<>"",(TODAY()-D16)>5),"RETARD","")
A17: TCD-2026-012 | B17: Douala, Cameroun | C17: Vehicule de secours 4x4 | D17: 46253 | E17: Manifeste de cargaison | F17: Obtenu | G17: 46256 | H17: A. Mbeki (transitaire) | I17: =IF(OR(F17="Obtenu",F17="Non applicable",D17=""),"",TODAY()-D17) | J17: =IF(AND(F17<>"Obtenu",F17<>"Non applicable",D17<>"",(TODAY()-D17)>5),"RETARD","")
A18: TCD-2026-012 | B18: Douala, Cameroun | C18: Vehicule de secours 4x4 | D18: 46253 | E18: Autorisation ministerielle complementaire (si applicable) | F18: Non applicable | I18: =IF(OR(F18="Obtenu",F18="Non applicable",D18=""),"",TODAY()-D18) | J18: =IF(AND(F18<>"Obtenu",F18<>"Non applicable",D18<>"",(TODAY()-D18)>5),"RETARD","")
A19: TCD-2026-014 | B19: Douala, Cameroun | C19: Concentrateurs oxygene + kits chirurgicaux + glaciere solaire | D19: 46261 | E19: Facture commerciale | F19: Obtenu | G19: 46261 | H19: A. Mbeki (transitaire) | I19: =IF(OR(F19="Obtenu",F19="Non applicable",D19=""),"",TODAY()-D19) | J19: =IF(AND(F19<>"Obtenu",F19<>"Non applicable",D19<>"",(TODAY()-D19)>5),"RETARD","")
A20: TCD-2026-014 | B20: Douala, Cameroun | C20: Concentrateurs oxygene + kits chirurgicaux + glaciere solaire | D20: 46261 | E20: Liste de colisage (packing list) | F20: Obtenu | G20: 46261 | H20: A. Mbeki (transitaire) | I20: =IF(OR(F20="Obtenu",F20="Non applicable",D20=""),"",TODAY()-D20) | J20: =IF(AND(F20<>"Obtenu",F20<>"Non applicable",D20<>"",(TODAY()-D20)>5),"RETARD","")
A21: TCD-2026-014 | B21: Douala, Cameroun | C21: Concentrateurs oxygene + kits chirurgicaux + glaciere solaire | D21: 46261 | E21: Certificat d'origine | F21: Obtenu | G21: 46262 | H21: A. Mbeki (transitaire) | I21: =IF(OR(F21="Obtenu",F21="Non applicable",D21=""),"",TODAY()-D21) | J21: =IF(AND(F21<>"Obtenu",F21<>"Non applicable",D21<>"",(TODAY()-D21)>5),"RETARD","")
A22: TCD-2026-014 | B22: Douala, Cameroun | C22: Concentrateurs oxygene + kits chirurgicaux + glaciere solaire | D22: 46261 | E22: Demande d'exoneration douaniere | F22: Bloque | H22: Douane - code HS a corriger | I22: =IF(OR(F22="Obtenu",F22="Non applicable",D22=""),"",TODAY()-D22) | J22: =IF(AND(F22<>"Obtenu",F22<>"Non applicable",D22<>"",(TODAY()-D22)>5),"RETARD","")
A23: TCD-2026-014 | B23: Douala, Cameroun | C23: Concentrateurs oxygene + kits chirurgicaux + glaciere solaire | D23: 46261 | E23: Autorisation d'importation | F23: Obtenu | G23: 46262 | H23: A. Mbeki (transitaire) | I23: =IF(OR(F23="Obtenu",F23="Non applicable",D23=""),"",TODAY()-D23) | J23: =IF(AND(F23<>"Obtenu",F23<>"Non applicable",D23<>"",(TODAY()-D23)>5),"RETARD","")
A24: TCD-2026-014 | B24: Douala, Cameroun | C24: Concentrateurs oxygene + kits chirurgicaux + glaciere solaire | D24: 46261 | E24: Manifeste de cargaison | F24: Obtenu | G24: 46262 | H24: A. Mbeki (transitaire) | I24: =IF(OR(F24="Obtenu",F24="Non applicable",D24=""),"",TODAY()-D24) | J24: =IF(AND(F24<>"Obtenu",F24<>"Non applicable",D24<>"",(TODAY()-D24)>5),"RETARD","")
A25: TCD-2026-014 | B25: Douala, Cameroun | C25: Concentrateurs oxygene + kits chirurgicaux + glaciere solaire | D25: 46261 | E25: Autorisation ministerielle complementaire (si applicable) | F25: En attente | H25: Ministere de la Sante | I25: =IF(OR(F25="Obtenu",F25="Non applicable",D25=""),"",TODAY()-D25) | J25: =IF(AND(F25<>"Obtenu",F25<>"Non applicable",D25<>"",(TODAY()-D25)>5),"RETARD","")
A26: A COMPLETER | E26: Facture commerciale | F26: En attente | I26: =IF(OR(F26="Obtenu",F26="Non applicable",D26=""),"",TODAY()-D26) | J26: =IF(AND(F26<>"Obtenu",F26<>"Non applicable",D26<>"",(TODAY()-D26)>5),"RETARD","")
A27: A COMPLETER | E27: Liste de colisage (packing list) | F27: En attente | I27: =IF(OR(F27="Obtenu",F27="Non applicable",D27=""),"",TODAY()-D27) | J27: =IF(AND(F27<>"Obtenu",F27<>"Non applicable",D27<>"",(TODAY()-D27)>5),"RETARD","")
A28: A COMPLETER | E28: Certificat d'origine | F28: En attente | I28: =IF(OR(F28="Obtenu",F28="Non applicable",D28=""),"",TODAY()-D28) | J28: =IF(AND(F28<>"Obtenu",F28<>"Non applicable",D28<>"",(TODAY()-D28)>5),"RETARD","")
A29: A COMPLETER | E29: Demande d'exoneration douaniere | F29: En attente | I29: =IF(OR(F29="Obtenu",F29="Non applicable",D29=""),"",TODAY()-D29) | J29: =IF(AND(F29<>"Obtenu",F29<>"Non applicable",D29<>"",(TODAY()-D29)>5),"RETARD","")
A30: A COMPLETER | E30: Autorisation d'importation | F30: En attente | I30: =IF(OR(F30="Obtenu",F30="Non applicable",D30=""),"",TODAY()-D30) | J30: =IF(AND(F30<>"Obtenu",F30<>"Non applicable",D30<>"",(TODAY()-D30)>5),"RETARD","")
A31: A COMPLETER | E31: Manifeste de cargaison | F31: En attente | I31: =IF(OR(F31="Obtenu",F31="Non applicable",D31=""),"",TODAY()-D31) | J31: =IF(AND(F31<>"Obtenu",F31<>"Non applicable",D31<>"",(TODAY()-D31)>5),"RETARD","")
A32: A COMPLETER | E32: Autorisation ministerielle complementaire (si applicable) | F32: En attente | I32: =IF(OR(F32="Obtenu",F32="Non applicable",D32=""),"",TODAY()-D32) | J32: =IF(AND(F32<>"Obtenu",F32<>"Non applicable",D32<>"",(TODAY()-D32)>5),"RETARD","")
E33: Facture commerciale | F33: En attente | I33: =IF(OR(F33="Obtenu",F33="Non applicable",D33=""),"",TODAY()-D33) | J33: =IF(AND(F33<>"Obtenu",F33<>"Non applicable",D33<>"",(TODAY()-D33)>5),"RETARD","")
E34: Liste de colisage (packing list) | F34: En attente | I34: =IF(OR(F34="Obtenu",F34="Non applicable",D34=""),"",TODAY()-D34) | J34: =IF(AND(F34<>"Obtenu",F34<>"Non applicable",D34<>"",(TODAY()-D34)>5),"RETARD","")
E35: Certificat d'origine | F35: En attente | I35: =IF(OR(F35="Obtenu",F35="Non applicable",D35=""),"",TODAY()-D35) | J35: =IF(AND(F35<>"Obtenu",F35<>"Non applicable",D35<>"",(TODAY()-D35)>5),"RETARD","")
E36: Demande d'exoneration douaniere | F36: En attente | I36: =IF(OR(F36="Obtenu",F36="Non applicable",D36=""),"",TODAY()-D36) | J36: =IF(AND(F36<>"Obtenu",F36<>"Non applicable",D36<>"",(TODAY()-D36)>5),"RETARD","")
E37: Autorisation d'importation | F37: En attente | I37: =IF(OR(F37="Obtenu",F37="Non applicable",D37=""),"",TODAY()-D37) | J37: =IF(AND(F37<>"Obtenu",F37<>"Non applicable",D37<>"",(TODAY()-D37)>5),"RETARD","")
E38: Manifeste de cargaison | F38: En attente | I38: =IF(OR(F38="Obtenu",F38="Non applicable",D38=""),"",TODAY()-D38) | J38: =IF(AND(F38<>"Obtenu",F38<>"Non applicable",D38<>"",(TODAY()-D38)>5),"RETARD","")
E39: Autorisation ministerielle complementaire (si applicable) | F39: En attente | I39: =IF(OR(F39="Obtenu",F39="Non applicable",D39=""),"",TODAY()-D39) | J39: =IF(AND(F39<>"Obtenu",F39<>"Non applicable",D39<>"",(TODAY()-D39)>5),"RETARD","")
E40: Facture commerciale | F40: En attente | I40: =IF(OR(F40="Obtenu",F40="Non applicable",D40=""),"",TODAY()-D40) | J40: =IF(AND(F40<>"Obtenu",F40<>"Non applicable",D40<>"",(TODAY()-D40)>5),"RETARD","")
E41: Liste de colisage (packing list) | F41: En attente | I41: =IF(OR(F41="Obtenu",F41="Non applicable",D41=""),"",TODAY()-D41) | J41: =IF(AND(F41<>"Obtenu",F41<>"Non applicable",D41<>"",(TODAY()-D41)>5),"RETARD","")
...

Sheet Tableau de bord
A1: TABLEAU DE BORD - SUIVI DES DOSSIERS DE DEDOUANEMENT
A2: Formation en Logistique Humanitaire · Module 06 · BK-BOOST Ltd.
A5: Shipment ID | B5: Documents requis | C5: Documents obtenus | D5: % complet | E5: Documents en retard | F5: Statut global
A6: TCD-2026-011 | B6: =COUNTIFS('Suivi dossiers'!$A:$A,A6,'Suivi dossiers'!$F:$F,"<>Non applicable",'Suivi dossiers'!$A:$A,"<>") | C6: =COUNTIFS('Suivi dossiers'!$A:$A,A6,'Suivi dossiers'!$F:$F,"Obtenu") | D6: =IF(B6=0,"",C6/B6) | E6: =COUNTIFS('Suivi dossiers'!$A:$A,A6,'Suivi dossiers'!$J:$J,"RETARD") | F6: =IF(B6=0,"-",IF(D6=1,"Dossier complet",IF(E6>0,"A ESCALADER","En cours")))
A7: TCD-2026-012 | B7: =COUNTIFS('Suivi dossiers'!$A:$A,A7,'Suivi dossiers'!$F:$F,"<>Non applicable",'Suivi dossiers'!$A:$A,"<>") | C7: =COUNTIFS('Suivi dossiers'!$A:$A,A7,'Suivi dossiers'!$F:$F,"Obtenu") | D7: =IF(B7=0,"",C7/B7) | E7: =COUNTIFS('Suivi dossiers'!$A:$A,A7,'Suivi dossiers'!$J:$J,"RETARD") | F7: =IF(B7=0,"-",IF(D7=1,"Dossier complet",IF(E7>0,"A ESCALADER","En cours")))
A8: TCD-2026-014 | B8: =COUNTIFS('Suivi dossiers'!$A:$A,A8,'Suivi dossiers'!$F:$F,"<>Non applicable",'Suivi dossiers'!$A:$A,"<>") | C8: =COUNTIFS('Suivi dossiers'!$A:$A,A8,'Suivi dossiers'!$F:$F,"Obtenu") | D8: =IF(B8=0,"",C8/B8) | E8: =COUNTIFS('Suivi dossiers'!$A:$A,A8,'Suivi dossiers'!$J:$J,"RETARD") | F8: =IF(B8=0,"-",IF(D8=1,"Dossier complet",IF(E8>0,"A ESCALADER","En cours")))
A9: A COMPLETER | B9: =COUNTIFS('Suivi dossiers'!$A:$A,A9,'Suivi dossiers'!$F:$F,"<>Non applicable",'Suivi dossiers'!$A:$A,"<>") | C9: =COUNTIFS('Suivi dossiers'!$A:$A,A9,'Suivi dossiers'!$F:$F,"Obtenu") | D9: =IF(B9=0,"",C9/B9) | E9: =COUNTIFS('Suivi dossiers'!$A:$A,A9,'Suivi dossiers'!$J:$J,"RETARD") | F9: =IF(B9=0,"-",IF(D9=1,"Dossier complet",IF(E9>0,"A ESCALADER","En cours")))
A11: Un dossier passe automatiquement en "A ESCALADER" des qu'au moins un document est en attente ou bloque depuis plus de 5 jours ouvres apres l'ouverture du dossier.
